Workbook

Sheet Klienci
A1: ID_Klienta | B1: Klient | C1: Segment | D1: ID_Regionu | E1: Miasto
A2: K0001 | B2: Adam Jankowska | C2: Korporacyjny | D2: R02 | E2: Kraków
A3: K0002 | B3: Natalia Zielińska | C3: Detaliczny | D3: R01 | E3: Warszawa
A4: K0003 | B4: Łukasz Krawczyk | C4: Mała firma | D4: R01 | E4: Warszawa
A5: K0004 | B5: Piotr Wójcik | C5: Korporacyjny | D5: R02 | E5: Kraków
A6: K0005 | B6: Katarzyna Kozłowski | C6: Mała firma | D6: R01 | E6: Warszawa
A7: K0006 | B7: Adam Jankowska | C7: Detaliczny | D7: R01 | E7: Warszawa
A8: K0007 | B8: Jakub Szymański | C8: Detaliczny | D8: R02 | E8: Kraków
A9: K0008 | B9: Ewa Mazur | C9: Korporacyjny | D9: R03 | E9: Wrocław
A10: K0009 | B10: Agnieszka Krawczyk | C10: Korporacyjny | D10: R04 | E10: Gdańsk
A11: K0010 | B11: Kamil Lewandowski | C11: Korporacyjny | D11: R02 | E11: Kraków
A12: K0011 | B12: Aleksandra Krawczyk | C12: Korporacyjny | D12: R03 | E12: Wrocław
... A38: K0037 | B38: Piotr Woźniak | C38: Mała firma | D38: R01 | E38: Warszawa
A39: K0038 | B39: Ewa Wiśniewska | D39: R05 | E39: Lublin
A40: K0039 | B40: Katarzyna Mazur | C40: Detaliczny | D40: R05 | E40: Lublin
A41: K0040 | B41: Katarzyna Dąbrowska | C41: Detaliczny | D41: R01 | E41: Warszawa
A42: K0041 | B42: Marek Krawczyk | C42: Korporacyjny | D42: R04 | E42: Gdańsk
A43: K0042 | B43: Piotr Woźniak | C43: Detaliczny | D43: R02 | E43: Kraków
A44: K0043 | B44: Ewa Kamińska | C44: Mała firma | D44: R04 | E44: Gdańsk
A45: K0044 | B45: Natalia Wójcik | C45: Mała firma | D45: R02 | E45: Kraków
A46: K0045 | B46: Joanna Dąbrowska | C46: Korporacyjny | D46: R04 | E46: Gdańsk
A47: K0046 | B47: Aleksandra Kamińska | C47: Detaliczny | D47: R03 | E47: Wrocław
A48: K0047 | B48: Aleksandra Woźniak | C48: Korporacyjny | D48: R01 | E48: Warszawa
A49: K0048 | B49: Katarzyna Szymański | C49: Detaliczny | D49: R01 | E49: Warszawa
A50: K0049 | B50: Monika Wiśniewska | C50: Mała firma | D50: R05 | E50: Lublin
A51: K0050 | B51: Paweł Kamińska | C51: Mała firma | D51: R01 | E51: Warszawa
... A129: K0128 | B129: Katarzyna Dąbrowska | C129: Mała firma | D129: R01 | E129: Warszawa
A130: K0129 | B130: Aleksandra Wiśniewska | D130: R02 | E130: Kraków
A131: K0130 | B131: Magdalena Kamińska | C131: Detaliczny | D131: R03 | E131: Wrocław
A132: K0131 | B132: Natalia Kamińska | C132: Mała firma | D132: R04 | E132: Gdańsk
A133: K0132 | B133: Michał Kowalczyk | C133: Detaliczny | D133: R03 | E133: Wrocław
A134: K0133 | B134: Anna Kozłowski | C134: Korporacyjny | D134: R04 | E134: Gdańsk
A135: K0134 | B135: Łukasz Wójcik | C135: Korporacyjny | D135: R01 | E135: Warszawa
A136: K0135 | B136: Piotr Jankowska | C136: Detaliczny | D136: R01 | E136: Warszawa
A137: K0136 | B137: Agnieszka Mazur | C137: Detaliczny | D137: R02 | E137: Kraków
A138: K0137 | B138: Joanna Wójcik | C138: Detaliczny | D138: R05 | E138: Lublin
A139: K0138 | B139: Marek Woźniak | C139: Detaliczny | D139: R04 | E139: Gdańsk
A140: K0139 | B140: Monika Jankowska | C140: Mała firma | D140: R04 | E140: Gdańsk
A141: K0140 | B141: Marek Jankowska | C141: Detaliczny | D141: R02 | E141: Kraków
A142: K0141 | B142: Marek Woźniak | C142: Detaliczny | D142: R03 | E142: Wrocław
...

Sheet Produkty
A1: ID_Produktu | B1: Produkt | C1: Kategoria | D1: Koszt_Jedn | E1: Cena_Katalogowa
A2: P001 | B2: Słuchawki 1 | C2: Elektronika | D2: 451.93 | E2: 558.48
A3: P002 | B3: Słuchawki 2 | C3: Elektronika | D3: 201.22 | E3: 273.78
A4: P003 | B4: Słuchawki 3 | C4: Elektronika | D4: 518.69 | E4: 853.93
A5: P004 | B5: Słuchawki 4 | C5: Elektronika | D5: 625.82 | E5: 797.78
A6: P005 | B6: Klawiatura 1 | C6: Elektronika | D6: 302.28 | E6: 374.46
A7: P006 | B7: Klawiatura 2 | C7: Elektronika | D7: 162.42 | E7: 249.86
A8: P007 | B8: Klawiatura 3 | C8: Elektronika | D8: 30.26 | E8: 40.71
A9: P008 | B9: Klawiatura 4 | C9: Elektronika | D9: 459.12 | E9: 717.75
A10: P009 | B10: Mysz 1 | C10: Elektronika | D10: 163.66 | E10: 260.42
A11: P010 | B11: Mysz 2 | C11: Elektronika | D11: 568.89 | E11: 696.37
A12: P011 | B12: Mysz 3 | C12: Elektronika | D12: 566.4 | E12: 940.13
A13: P012 | B13: Mysz 4 | C13: Elektronika | D13: 246.09 | E13: 324.33
... A61: P060 | B61: Ładowarka 4 | C61: Akcesoria | D61: 430.97 | E61: 567.28

Sheet Regiony
A1: ID_Regionu | B1: Region | C1: Miasto_Glowne
A2: R01 | B2: Centralny | C2: Warszawa
A3: R02 | B3: Południowy | C3: Kraków
A4: R03 | B4: Zachodni | C4: Wrocław
A5: R04 | B5: Północny | C5: Gdańsk
A6: R05 | B6: Wschodni | C6: Lublin

Sheet Zamowienia
A1: ID_Zamowienia | B1: Data_Zamowienia | C1: ID_Klienta | D1: ID_Regionu | E1: Kanal | F1: Status
A2: Z00001 | B2: 2025-05-29 | C2: K0222 | D2: R04 | E2: Telefon | F2: Zrealizowane
A3: Z00002 | B3: 2025-12-27 | C3: K0166 | D3: R03 | E3: Online | F3: Anulowane
A4: Z00003 | B4: 2025-08-29 | C4: K0087 | D4: R03 | E4: Telefon | F4: Zrealizowane
A5: Z00004 | B5: 2025-08-08 | C5: K0393 | D5: R01 | E5: Online | F5: Zrealizowane
A6: Z00005 | B6: 2025-04-20 | C6: K0248 | D6: R04 | E6: Online | F6: Zrealizowane
A7: Z00006 | B7: 2025-04-22 | C7: K0124 | D7: R04 | E7: Online | F7: Zrealizowane
A8: Z00007 | B8: 2024-06-12 | C8: K0444 | D8: R03 | E8: Sklep | F8: Anulowane
A9: Z00008 | B9: 2024-08-08 | C9: K0124 | D9: R04 | E9: Sklep | F9: Zrealizowane
A10: Z00009 | B10: 2025-01-09 | C10: K0373 | D10: R03 | E10: Sklep | F10: Zrealizowane
A11: Z00010 | B11: 2024-04-09 | C11: K0500 | D11: R05 | E11: Online | F11: Zrealizowane
A12: Z00011 | B12: 2025-04-30 | C12: K0412 | D12: R05 | E12: Online | F12: Zrealizowane
... A9001: Z09000 | B9001: 2024-08-31 | C9001: K0457 | D9001: R03 | E9001: Telefon | F9001: Zrealizowane

Sheet Pozycje
A1: ID_Pozycji | B1: ID_Zamowienia | C1: ID_Produktu | D1: Ilosc | E1: Cena_Jedn | F1: Rabat | G1: Nazwa Produktu | H1: Wartość sprzedaży | I1: Wielkosc transakcji
A2: L000001 | B2: Z00001 | C2: P034 | D2: 2 | E2: 206.1 | F2: 0 | G2: =VLOOKUP(C2:C22539,Produkty!$A$2:$B$61,2,0) -> Czajnik 2 | H2: =D2*E2*(1-F2) -> 412.2 | I2: =IF(H2<500,"Mała",IF(H2<=2000,"Średnia","Duża")) -> Mała
A3: L000002 | B3: Z00002 | C3: P055 | D3: 1 | E3: 579.5 | F3: 0 | G3: =VLOOKUP(C3:C22540,Produkty!$A$2:$B$61,2,0) -> Podkładka 3 | H3: =D3*E3*(1-F3) -> 579.5 | I3: =IF(H3<500,"Mała",IF(H3<=2000,"Średnia","Duża")) -> Średnia
A4: L000003 | B4: Z00002 | C4: P036 | D4: 3 | E4: 287.23 | F4: 0 | G4: =VLOOKUP(C4:C22541,Produkty!$A$2:$B$61,2,0) -> Czajnik 4 | H4: =D4*E4*(1-F4) -> 861.69 | I4: =IF(H4<500,"Mała",IF(H4<=2000,"Średnia","Duża")) -> Średnia
A5: L000004 | B5: Z00002 | C5: P040 | D5: 5 | E5: 267.19 | F5: 0 | G5: =VLOOKUP(C5:C22542,Produkty!$A$2:$B$61,2,0) -> Termos 4 | H5: =D5*E5*(1-F5) -> 1335.95 | I5: =IF(H5<500,"Mała",IF(H5<=2000,"Średnia","Duża")) -> Średnia
A6: L000005 | B6: Z00003 | C6: P054 | D6: 5 | E6: 135.17 | F6: 0 | G6: =VLOOKUP(C6:C22543,Produkty!$A$2:$B$61,2,0) -> Podkładka 2 | H6: =D6*E6*(1-F6) -> 675.85 | I6: =IF(H6<500,"Mała",IF(H6<=2000,"Średnia","Duża")) -> Średnia
A7: L000006 | B7: Z00003 | C7: P002 | D7: 1 | E7: 281.15 | F7: 0 | G7: =VLOOKUP(C7:C22544,Produkty!$A$2:$B$61,2,0) -> Słuchawki 2 | H7: =D7*E7*(1-F7) -> 281.15 | I7: =IF(H7<500,"Mała",IF(H7<=2000,"Średnia","Duża")) -> Mała
A8: L000007 | B8: Z00003 | C8: P050 | D8: 5 | E8: 1209.4 | F8: 0 | G8: =VLOOKUP(C8:C22545,Produkty!$A$2:$B$61,2,0) -> Hub USB 2 | H8: =D8*E8*(1-F8) -> 6047 | I8: =IF(H8<500,"Mała",IF(H8<=2000,"Średnia","Duża")) -> Duża
A9: L000008 | B9: Z00004 | C9: P057 | D9: 6 | E9: 468.93 | F9: 0.1 | G9: =VLOOKUP(C9:C22546,Produkty!$A$2:$B$61,2,0) -> Ładowarka 1 | H9: =D9*E9*(1-F9) -> 2532.222 | I9: =IF(H9<500,"Mała",IF(H9<=2000,"Średnia","Duża")) -> Duża
A10: L000009 | B10: Z00004 | C10: P020 | D10: 4 | E10: 975.43 | F10: 0 | G10: =VLOOKUP(C10:C22547,Produkty!$A$2:$B$61,2,0) -> Powerbank 4 | H10: =D10*E10*(1-F10) -> 3901.72 | I10: =IF(H10<500,"Mała",IF(H10<=2000,"Średnia","Duża")) -> Duża
A11: L000010 | B11: Z00004 | C11: P044 | D11: 4 | E11: 1073.1 | F11: 0 | G11: =VLOOKUP(C11:C22548,Produkty!$A$2:$B$61,2,0) -> Kabel USB-C 4 | H11: =D11*E11*(1-F11) -> 4292.4 | I11: =IF(H11<500,"Mała",IF(H11<=2000,"Średnia","Duża")) -> Duża
A12: L000011 | B12: Z00004 | C12: P045 | D12: 1 | E12: 92.82 | F12: 0 | G12: =VLOOKUP(C12:C22549,Produkty!$A$2:$B$61,2,0) -> Etui 1 | H12: =D12*E12*(1-F12) -> 92.82 | I12: =IF(H12<500,"Mała",IF(H12<=2000,"Średnia","Duża")) -> Mała
A13: L000012 | B13: Z00005 | C13: P056 | D13: 6 | E13: 863.75 | F13: 0 | G13: =VLOOKUP(C13:C22550,Produkty!$A$2:$B$61,2,0) -> Podkładka 4 | H13: =D13*E13*(1-F13) -> 5182.5 | I13: =IF(H13<500,"Mała",IF(H13<=2000,"Średnia","Duża")) -> Duża
... A22539: L022538 | B22539: Z00314 | C22539: P034 | D22539: 6 | E22539: 206.61 | F22539: 0 | G22539: =VLOOKUP(C22539:C45076,Produkty!$A$2:$B$61,2,0) -> Czajnik 2 | H22539: =D22539*E22539*(1-F22539) -> 1239.66 | I22539: =IF(H22539<500,"Mała",IF(H22539<=2000,"Średnia","Duża")) -> Średnia

Sheet Cele
A1: Miesiac | B1: ID_Regionu | C1: Cel_Sprzedazy
A2: 2024-01 | B2: R01 | C2: 308611.18
A3: 2024-01 | B3: R02 | C3: 277608.72
A4: 2024-01 | B4: R03 | C4: 180581.32
A5: 2024-01 | B5: R04 | C5: 250957.32
A6: 2024-01 | B6: R05 | C6: 259430.61
A7: 2024-02 | B7: R01 | C7: 267933.43
A8: 2024-02 | B8: R02 | C8: 188312.01
A9: 2024-02 | B9: R03 | C9: 244573.93
A10: 2024-02 | B10: R04 | C10: 287249.66
A11: 2024-02 | B11: R05 | C11: 263334.27
A12: 2024-03 | B12: R01 | C12: 189667.75
A13: 2024-03 | B13: R02 | C13: 318681.58
... A121: 2025-12 | B121: R05 | C121: 284415.16

Sheet Zamowienia analiza
A3: Etykiety wierszy | B3: Liczba wartości odrębnych ID_Zamowienia | C3: Suma Wartość sprzedaży
A4: Anulowane | B4: 630 | C4: 2835310.6
A5: Zrealizowane | B5: 8370 | C5: 37608202
A6: Suma końcowa | B6: 9000 | C6: 40443512
A11: Etykiety wierszy | B11: Suma Wartość sprzedaży
A12: Anulowane | B12: 2835310.6
A13: Zrealizowane | B13: 37608202
A14: Suma końcowa | B14: 40443512

Sheet Sprzedaż na wielk. transakcji
A3: Etykiety wierszy | B3: Suma z Wartość sprzedaży
A4: Duża | B4: 27582767
A5: Mała | B5: 1206973.3
A6: Średnia | B6: 11653772
A7: Suma końcowa | B7: 40443512
